Traceback (most recent call last):
  File "/opt/anaconda3/envs/jupyterbook_env/lib/python3.9/site-packages/jupyter_cache/executors/utils.py", line 58, in single_nb_execution
    executenb(
  File "/opt/anaconda3/envs/jupyterbook_env/lib/python3.9/site-packages/nbclient/client.py", line 1319, in execute
    return NotebookClient(nb=nb, resources=resources, km=km, **kwargs).execute()
  File "/opt/anaconda3/envs/jupyterbook_env/lib/python3.9/site-packages/jupyter_core/utils/__init__.py", line 165, in wrapped
    return loop.run_until_complete(inner)
  File "/opt/anaconda3/envs/jupyterbook_env/lib/python3.9/asyncio/base_events.py", line 647, in run_until_complete
    return future.result()
  File "/opt/anaconda3/envs/jupyterbook_env/lib/python3.9/site-packages/nbclient/client.py", line 709, in async_execute
    await self.async_execute_cell(
  File "/opt/anaconda3/envs/jupyterbook_env/lib/python3.9/site-packages/nbclient/client.py", line 1062, in async_execute_cell
    await self._check_raise_for_error(cell, cell_index, exec_reply)
  File "/opt/anaconda3/envs/jupyterbook_env/lib/python3.9/site-packages/nbclient/client.py", line 918, in _check_raise_for_error
    raise CellExecutionError.from_cell_and_msg(cell, exec_reply_content)
nbclient.exceptions.CellExecutionError: An error occurred while executing the following cell:
------------------
import pandas as pd
import sqlite3
from sqlite3 import Error
import os

# Function to create a database connecti`on
def create_connection(db_file, delete_db=False):
    if delete_db and os.path.exists(db_file):
        os.remove(db_file)

    conn = None
    try:
        conn = sqlite3.connect(db_file)
        conn.execute("PRAGMA foreign_keys = 1")
    except Error as e:
        print(e)

    return conn

# Function to create tables
def create_table(conn, create_table_sql, drop_table_name=None):
    if drop_table_name:  # Drop table if specified
        try:
            c = conn.cursor()
            c.execute(f"DROP TABLE IF EXISTS {drop_table_name}")
        except Error as e:
            print(e)

    try:
        c = conn.cursor()
        c.execute(create_table_sql)
    except Error as e:
        print(e)
------------------


[0;31m---------------------------------------------------------------------------[0m
[0;31mModuleNotFoundError[0m                       Traceback (most recent call last)
Cell [0;32mIn[1], line 1[0m
[0;32m----> 1[0m [38;5;28;01mimport[39;00m [38;5;21;01mpandas[39;00m [38;5;28;01mas[39;00m [38;5;21;01mpd[39;00m
[1;32m      2[0m [38;5;28;01mimport[39;00m [38;5;21;01msqlite3[39;00m
[1;32m      3[0m [38;5;28;01mfrom[39;00m [38;5;21;01msqlite3[39;00m [38;5;28;01mimport[39;00m Error

[0;31mModuleNotFoundError[0m: No module named 'pandas'

